Workbook

Sheet 01_Analise_Origem
A3: Rótulos de Linha | B3: Contagem de LEAD_ID | C3: Soma de FLAG_CONVERSAO | D3: TAXA DE CONVERSÃO
A4: Bing | B4: 78 | C4: 2 | D4: =IFERROR(C4/B4,0) -> 0.025641026
A5: email | B5: 27 | C5: 1 | D5: =IFERROR(C5/B5,0) -> 0.037037037
A6: Facebook | B6: 279 | C6: 1 | D6: =IFERROR(C6/B6,0) -> 0.0035842294
A7: Google | B7: 797 | C7: 35 | D7: =IFERROR(C7/B7,0) -> 0.04391468
A8: Inbound Marketing | B8: 4 | C8: 1 | D8: =IFERROR(C8/B8,0) -> 0.25
A9: Indicação | B9: 2 | C9: 1 | D9: =IFERROR(C9/B9,0) -> 0.5
A10: Instagram | B10: 59 | C10: 0 | D10: =IFERROR(C10/B10,0) -> 0
A11: Leads | B11: 35 | C11: 1 | D11: =IFERROR(C11/B11,0) -> 0.028571429
A12: Linkedin | B12: 15 | C12: 0 | D12: =IFERROR(C12/B12,0) -> 0
A13: Orgânico | B13: 707 | C13: 30 | D13: =IFERROR(C13/B13,0) -> 0.042432815
A14: Prospecção Ativa | B14: 188 | C14: 0 | D14: =IFERROR(C14/B14,0) -> 0
A15: rep | B15: 24 | C15: 0 | D15: =IFERROR(C15/B15,0) -> 0
... A17: Total Geral | B17: 2271 | C17: 72 | D17: =IFERROR(C17/B17,0) -> 0.031704095

Sheet 02_Analise_Mercado
A3: Rótulos de Linha | B3: Contagem de LEAD_ID | C3: Soma de FLAG_CONVERSAO | D3: TAXA DE CONVERSÃO
A4: Empreendedor | B4: 488 | C4: 10 | D4: =IFERROR(C4/B4,0) -> 0.020491803
A5: Franqueadora | B5: 202 | C5: 12 | D5: =IFERROR(C5/B5,0) -> 0.059405941
A6: Imobiliaria/Incorporadora/Construtora | B6: 169 | C6: 3 | D6: =IFERROR(C6/B6,0) -> 0.017751479
A7: Industria | B7: 149 | C7: 6 | D7: =IFERROR(C7/B7,0) -> 0.040268456
A8: Marketing/Publicidade/Consultoria | B8: 166 | C8: 9 | D8: =IFERROR(C8/B8,0) -> 0.054216867
A9: Servicos | B9: 566 | C9: 16 | D9: =IFERROR(C9/B9,0) -> 0.028268551
A10: Tecnologia | B10: 149 | C10: 5 | D10: =IFERROR(C10/B10,0) -> 0.033557047
A11: Varejo | B11: 287 | C11: 9 | D11: =IFERROR(C11/B11,0) -> 0.031358885
A12: Total Geral | B12: 2176 | C12: 70 | D12: =IFERROR(C12/B12,0) -> 0.032169118

Sheet 03_Analise_Porte
A3: Rótulos de Linha | B3: Contagem de LEAD_ID | C3: Soma de FLAG_CONVERSAO | D3: TAXA DE CONVERSÃO
A4: + 1000 | B4: 55 | C4: 0 | D4: =IFERROR(C4/B4,0) -> 0
A5: 1-10 | B5: 820 | C5: 33 | D5: =IFERROR(C5/B5,0) -> 0.040243902
A6: 11-50 | B6: 285 | C6: 19 | D6: =IFERROR(C6/B6,0) -> 0.066666667
A7: 301-1000 | B7: 36 | C7: 3 | D7: =IFERROR(C7/B7,0) -> 0.083333333
A8: 51-300 | B8: 140 | C8: 11 | D8: =IFERROR(C8/B8,0) -> 0.078571429
A9: Total Geral | B9: 1336 | C9: 66 | D9: =IFERROR(C9/B9,0) -> 0.049401198

Sheet 04_Analise_Objetivo
A3: Rótulos de Linha | B3: Contagem de LEAD_ID | C3: Soma de FLAG_CONVERSAO | D3: TAXA DE CONVERSÃO
A4: 0 | B4: 213 | C4: 2 | D4: =IFERROR(C4/B4,0) -> 0.0093896714
A5: Abertura/Expansão | B5: 711 | C5: 36 | D5: =IFERROR(C5/B5,0) -> 0.050632911
A6: Ações de marketing/vendas | B6: 310 | C6: 9 | D6: =IFERROR(C6/B6,0) -> 0.029032258
A7: Consultoria | B7: 155 | C7: 8 | D7: =IFERROR(C7/B7,0) -> 0.051612903
A8: Geração de leads b2b | B8: 303 | C8: 4 | D8: =IFERROR(C8/B8,0) -> 0.01320132
A9: Outro | B9: 343 | C9: 4 | D9: =IFERROR(C9/B9,0) -> 0.011661808
A10: Planejamento estratégico | B10: 236 | C10: 9 | D10: =IFERROR(C10/B10,0) -> 0.038135593
A11: Total Geral | B11: 2271 | C11: 72 | D11: =IFERROR(C11/B11,0) -> 0.031704095

Sheet BASE_ANALISE
A1: LEAD_ID | B1: DATA CADASTRO | C1: VENDIDO | D1: MERCADO | E1: ORIGEM | F1: SUB-ORIGEM | G1: LOCAL | H1: PORTE | I1: OBJETIVO | J1: FLAG_CONVERSAO
A2: 11316042 | B2: 45698.683 | C2: NÃO | D2: =VLOOKUP(A2,MERCADO!A:B,2,0) -> Varejo | E2: =_xlfn.XLOOKUP(A2, ORIGEM!A:A, ORIGEM!B:B) -> Orgânico | F2: =_xlfn.XLOOKUP(A2, ORIGEM!A:A, ORIGEM!C:C) -> 0 | G2: =_xlfn.XLOOKUP(A2, LOCAL!A:A, LOCAL!B:B) -> Belém - PA | H2: =_xlfn.XLOOKUP(A2, PORTE!A:A, PORTE!B:B) -> 1-10 | I2: =_xlfn.XLOOKUP(A2, OBJETIVO!A:A, OBJETIVO!B:B) -> Abertura/Expansão | J2: =IF(C2="SIM",1,0) -> 0
A3: 11374979 | B3: 45705.466 | C3: NÃO | D3: =VLOOKUP(A3,MERCADO!A:B,2,0) -> Varejo | E3: =_xlfn.XLOOKUP(A3, ORIGEM!A:A, ORIGEM!B:B) -> Orgânico | F3: =_xlfn.XLOOKUP(A3, ORIGEM!A:A, ORIGEM!C:C) -> 0 | G3: =_xlfn.XLOOKUP(A3, LOCAL!A:A, LOCAL!B:B) -> São Paulo, SP | H3: =_xlfn.XLOOKUP(A3, PORTE!A:A, PORTE!B:B) -> 11-50 | I3: =_xlfn.XLOOKUP(A3, OBJETIVO!A:A, OBJETIVO!B:B) -> 0 | J3: =IF(C3="SIM",1,0) -> 0
A4: 11997870 | B4: 45762.463 | C4: NÃO | D4: =VLOOKUP(A4,MERCADO!A:B,2,0) -> Varejo | E4: =_xlfn.XLOOKUP(A4, ORIGEM!A:A, ORIGEM!B:B) -> Prospecção Ativa | F4: =_xlfn.XLOOKUP(A4, ORIGEM!A:A, ORIGEM!C:C) -> Sales Navigator | G4: =_xlfn.XLOOKUP(A4, LOCAL!A:A, LOCAL!B:B) -> - | H4: =_xlfn.XLOOKUP(A4, PORTE!A:A, PORTE!B:B) -> 0 | I4: =_xlfn.XLOOKUP(A4, OBJETIVO!A:A, OBJETIVO!B:B) -> 0 | J4: =IF(C4="SIM",1,0) -> 0
A5: 11930537 | B5: 45756.549 | C5: NÃO | D5: =VLOOKUP(A5,MERCADO!A:B,2,0) -> Varejo | E5: =_xlfn.XLOOKUP(A5, ORIGEM!A:A, ORIGEM!B:B) -> Prospecção Ativa | F5: =_xlfn.XLOOKUP(A5, ORIGEM!A:A, ORIGEM!C:C) -> Sales Navigator | G5: =_xlfn.XLOOKUP(A5, LOCAL!A:A, LOCAL!B:B) -> - | H5: =_xlfn.XLOOKUP(A5, PORTE!A:A, PORTE!B:B) -> 0 | I5: =_xlfn.XLOOKUP(A5, OBJETIVO!A:A, OBJETIVO!B:B) -> 0 | J5: =IF(C5="SIM",1,0) -> 0
A6: 11899381 | B6: 45754.551 | C6: NÃO | D6: =VLOOKUP(A6,MERCADO!A:B,2,0) -> Varejo | E6: =_xlfn.XLOOKUP(A6, ORIGEM!A:A, ORIGEM!B:B) -> Prospecção Ativa | F6: =_xlfn.XLOOKUP(A6, ORIGEM!A:A, ORIGEM!C:C) -> Sales Navigator | G6: =_xlfn.XLOOKUP(A6, LOCAL!A:A, LOCAL!B:B) -> - | H6: =_xlfn.XLOOKUP(A6, PORTE!A:A, PORTE!B:B) -> 0 | I6: =_xlfn.XLOOKUP(A6, OBJETIVO!A:A, OBJETIVO!B:B) -> 0 | J6: =IF(C6="SIM",1,0) -> 0
A7: 11899592 | B7: 45754.564 | C7: NÃO | D7: =VLOOKUP(A7,MERCADO!A:B,2,0) -> Varejo | E7: =_xlfn.XLOOKUP(A7, ORIGEM!A:A, ORIGEM!B:B) -> Prospecção Ativa | F7: =_xlfn.XLOOKUP(A7, ORIGEM!A:A, ORIGEM!C:C) -> Sales Navigator | G7: =_xlfn.XLOOKUP(A7, LOCAL!A:A, LOCAL!B:B) -> - | H7: =_xlfn.XLOOKUP(A7, PORTE!A:A, PORTE!B:B) -> 0 | I7: =_xlfn.XLOOKUP(A7, OBJETIVO!A:A, OBJETIVO!B:B) -> 0 | J7: =IF(C7="SIM",1,0) -> 0
A8: 11889399 | B8: 45753.693 | C8: NÃO | D8: =VLOOKUP(A8,MERCADO!A:B,2,0) -> Varejo | E8: =_xlfn.XLOOKUP(A8, ORIGEM!A:A, ORIGEM!B:B) -> Prospecção Ativa | F8: =_xlfn.XLOOKUP(A8, ORIGEM!A:A, ORIGEM!C:C) -> Sales Navigator | G8: =_xlfn.XLOOKUP(A8, LOCAL!A:A, LOCAL!B:B) -> - | H8: =_xlfn.XLOOKUP(A8, PORTE!A:A, PORTE!B:B) -> 0 | I8: =_xlfn.XLOOKUP(A8, OBJETIVO!A:A, OBJETIVO!B:B) -> 0 | J8: =IF(C8="SIM",1,0) -> 0
A9: 11842866 | B9: 45748.457 | C9: NÃO | D9: =VLOOKUP(A9,MERCADO!A:B,2,0) -> Varejo | E9: =_xlfn.XLOOKUP(A9, ORIGEM!A:A, ORIGEM!B:B) -> Prospecção Ativa | F9: =_xlfn.XLOOKUP(A9, ORIGEM!A:A, ORIGEM!C:C) -> Sales Navigator | G9: =_xlfn.XLOOKUP(A9, LOCAL!A:A, LOCAL!B:B) -> - | H9: =_xlfn.XLOOKUP(A9, PORTE!A:A, PORTE!B:B) -> 0 | I9: =_xlfn.XLOOKUP(A9, OBJETIVO!A:A, OBJETIVO!B:B) -> 0 | J9: =IF(C9="SIM",1,0) -> 0
A10: 11843011 | B10: 45748.465 | C10: NÃO | D10: =VLOOKUP(A10,MERCADO!A:B,2,0) -> Varejo | E10: =_xlfn.XLOOKUP(A10, ORIGEM!A:A, ORIGEM!B:B) -> Prospecção Ativa | F10: =_xlfn.XLOOKUP(A10, ORIGEM!A:A, ORIGEM!C:C) -> Sales Navigator | G10: =_xlfn.XLOOKUP(A10, LOCAL!A:A, LOCAL!B:B) -> - | H10: =_xlfn.XLOOKUP(A10, PORTE!A:A, PORTE!B:B) -> 0 | I10: =_xlfn.XLOOKUP(A10, OBJETIVO!A:A, OBJETIVO!B:B) -> 0 | J10: =IF(C10="SIM",1,0) -> 0
A11: 11684556 | B11: 45734.425 | C11: NÃO | D11: =VLOOKUP(A11,MERCADO!A:B,2,0) -> Varejo | E11: =_xlfn.XLOOKUP(A11, ORIGEM!A:A, ORIGEM!B:B) -> Prospecção Ativa | F11: =_xlfn.XLOOKUP(A11, ORIGEM!A:A, ORIGEM!C:C) -> Sales Navigator | G11: =_xlfn.XLOOKUP(A11, LOCAL!A:A, LOCAL!B:B) -> - | H11: =_xlfn.XLOOKUP(A11, PORTE!A:A, PORTE!B:B) -> 0 | I11: =_xlfn.XLOOKUP(A11, OBJETIVO!A:A, OBJETIVO!B:B) -> 0 | J11: =IF(C11="SIM",1,0) -> 0
A12: 11685062 | B12: 45734.437 | C12: NÃO | D12: =VLOOKUP(A12,MERCADO!A:B,2,0) -> Varejo | E12: =_xlfn.XLOOKUP(A12, ORIGEM!A:A, ORIGEM!B:B) -> Prospecção Ativa | F12: =_xlfn.XLOOKUP(A12, ORIGEM!A:A, ORIGEM!C:C) -> Sales Navigator | G12: =_xlfn.XLOOKUP(A12, LOCAL!A:A, LOCAL!B:B) -> - | H12: =_xlfn.XLOOKUP(A12, PORTE!A:A, PORTE!B:B) -> 0 | I12: =_xlfn.XLOOKUP(A12, OBJETIVO!A:A, OBJETIVO!B:B) -> 0 | J12: =IF(C12="SIM",1,0) -> 0
A13: 11698167 | B13: 45735.494 | C13: NÃO | D13: =VLOOKUP(A13,MERCADO!A:B,2,0) -> Varejo | E13: =_xlfn.XLOOKUP(A13, ORIGEM!A:A, ORIGEM!B:B) -> Prospecção Ativa | F13: =_xlfn.XLOOKUP(A13, ORIGEM!A:A, ORIGEM!C:C) -> Sales Navigator | G13: =_xlfn.XLOOKUP(A13, LOCAL!A:A, LOCAL!B:B) -> - | H13: =_xlfn.XLOOKUP(A13, PORTE!A:A, PORTE!B:B) -> 0 | I13: =_xlfn.XLOOKUP(A13, OBJETIVO!A:A, OBJETIVO!B:B) -> 0 | J13: =IF(C13="SIM",1,0) -> 0
... A2272: 11566253 | B2272: 45724.432 | C2272: NÃO | D2272: =VLOOKUP(A2272,MERCADO!A:B,2,0) -> Varejo | E2272: =_xlfn.XLOOKUP(A2272, ORIGEM!A:A, ORIGEM!B:B) -> Facebook | F2272: =_xlfn.XLOOKUP(A2272, ORIGEM!A:A, ORIGEM!C:C) -> facebook - cpc | G2272: =_xlfn.XLOOKUP(A2272, LOCAL!A:A, LOCAL!B:B) -> João Pessoa - PB | H2272: =_xlfn.XLOOKUP(A2272, PORTE!A:A, PORTE!B:B) -> 0 | I2272: =_xlfn.XLOOKUP(A2272, OBJETIVO!A:A, OBJETIVO!B:B) -> Abertura/Expansão | J2272: =IF(C2272="SIM",1,0) -> 0

Sheet ORIGEM
A1: LEAD_ID | B1: ORIGEM | C1: SUB-ORIGEM
A2: 11316042 | B2: Orgânico
A3: 11374979 | B3: Orgânico
A4: 11997870 | B4: Prospecção Ativa | C4: Sales Navigator
A5: 11930537 | B5: Prospecção Ativa | C5: Sales Navigator
A6: 11899381 | B6: Prospecção Ativa | C6: Sales Navigator
A7: 11899592 | B7: Prospecção Ativa | C7: Sales Navigator
A8: 11889399 | B8: Prospecção Ativa | C8: Sales Navigator
A9: 11842866 | B9: Prospecção Ativa | C9: Sales Navigator
A10: 11843011 | B10: Prospecção Ativa | C10: Sales Navigator
A11: 11684556 | B11: Prospecção Ativa | C11: Sales Navigator
A12: 11685062 | B12: Prospecção Ativa | C12: Sales Navigator
A13: 11698167 | B13: Prospecção Ativa | C13: Sales Navigator
A14: 11698312 | B14: Prospecção Ativa | C14: Sales Navigator
A15: 11684204 | B15: Prospecção Ativa | C15: Sales Navigator
... A34: 10608029 | B34: Google | C34: google - cpc
A35: 10590212 | B35: Orgânico
A36: 10590859 | B36: Orgânico
A37: 11390110 | B37: Orgânico
A38: 11899460 | B38: Prospecção Ativa | C38: Sales Navigator
A39: 11269120 | B39: Orgânico
A40: 11344672 | B40: Orgânico
A41: 11269632 | B41: Google | C41: google - cpc
A42: 11600384 | B42: Prospecção Ativa | C42: Sales Navigator
A43: 11600003 | B43: Prospecção Ativa | C43: Sales Navigator
A44: 11612125 | B44: Prospecção Ativa | C44: Sales Navigator
A45: 11612134 | B45: Prospecção Ativa | C45: Sales Navigator
A46: 11612150 | B46: Prospecção Ativa | C46: Sales Navigator
A47: 11684485 | B47: Prospecção Ativa | C47: Sales Navigator
A48: 11684795 | B48: Prospecção Ativa | C48: Sales Navigator
A49: 11684898 | B49: Prospecção Ativa | C49: Sales Navigator
A50: 11685013 | B50: Prospecção Ativa | C50: Sales Navigator
A51: 11714445 | B51: Prospecção Ativa | C51: Sales Navigator
A52: 11714617 | B52: Prospecção Ativa | C52: Sales Navigator
... A85: 11296113 | B85: Google | C85: google - cpc
A86: 11611811 | B86: Prospecção Ativa
A87: 11588015 | B87: Prospecção Ativa
A88: 11599660 | B88: Prospecção Ativa
A89: 11599672 | B89: Prospecção Ativa
A90: 11599681 | B90: Prospecção Ativa
...

Sheet MERCADO
A1: LEAD_ID | B1: MERCADO
A2: 11316042 | B2: Varejo
A3: 11374979 | B3: Varejo
A4: 11997870 | B4: Varejo
A5: 11930537 | B5: Varejo
A6: 11899381 | B6: Varejo
A7: 11899592 | B7: Varejo
A8: 11889399 | B8: Varejo
A9: 11842866 | B9: Varejo
A10: 11843011 | B10: Varejo
A11: 11684556 | B11: Varejo
A12: 11685062 | B12: Varejo
A13: 11698167 | B13: Varejo
... A29: 11741070 | B29: Varejo
A30: 10566142
A31: 10572176
A32: 10581011
A33: 10621157
A34: 10608029
A35: 10590212
A36: 10590859
A37: 11390110 | B37: Marketing/Publicidade/Consultoria
A38: 11899460 | B38: Tecnologia
A39: 11269120 | B39: Servicos
A40: 11344672 | B40: Servicos
A41: 11269632 | B41: Servicos
A42: 11600384 | B42: Franqueadora
A43: 11600003 | B43: Franqueadora
A44: 11612125 | B44: Franqueadora
A45: 11612134 | B45: Franqueadora
A46: 11612150 | B46: Franqueadora
A47: 11684485 | B47: Franqueadora
A48: 11684795 | B48: Franqueadora
... A165: 11220990 | B165: Industria
A166: 10586869
A167: 11348239 | B167: Marketing/Publicidade/Consultoria
A168: 11367824 | B168: Imobiliaria/Incorporadora/Construtora
A169: 11238880 | B169: Industria
A170: 11310421 | B170: Servicos
A171: 11280178 | B171: Servicos
...

Sheet LOCAL
A1: LEAD_ID | B1: LOCAL
A2: 11316042 | B2: Belém - PA
A3: 11374979 | B3: São Paulo, SP
A4: 11997870 | B4: -
A5: 11930537 | B5: -
A6: 11899381 | B6: -
A7: 11899592 | B7: -
A8: 11889399 | B8: -
A9: 11842866 | B9: -
A10: 11843011 | B10: -
A11: 11684556 | B11: -
A12: 11685062 | B12: -
A13: 11698167 | B13: -
... A2274: 11566253 | B2274: João Pessoa - PB

Sheet PORTE
A1: LEAD_ID | B1: PORTE
A2: 11316042 | B2: 1-10
A3: 11374979 | B3: 11-50
A4: 11997870
A5: 11930537
A6: 11899381
A7: 11899592
A8: 11889399
A9: 11842866
A10: 11843011
A11: 11684556
A12: 11685062
A13: 11698167
A14: 11698312
A15: 11684204
A16: 11684264
A17: 11357814 | B17: 0
A18: 11842580
A19: 11842668
A20: 11806208
A21: 11817123
A22: 11774094
A23: 11741460
A24: 11741181
A25: 11698497
A26: 11698513
A27: 11698524
A28: 11699034
A29: 11741070
A30: 10566142 | B30: 51-300
A31: 10572176 | B31: 1-10
A32: 10581011 | B32: 51-300
A33: 10621157 | B33: 1-10
A34: 10608029 | B34: 1-10
A35: 10590212 | B35: 1-10
A36: 10590859 | B36: 0
A37: 11390110 | B37: 1-10
A38: 11899460
A39: 11269120 | B39: 1-10
A40: 11344672 | B40: + 1000
...

Sheet OBJETIVO
A1: LEAD_ID | B1: OBJETIVO
A2: 11316042 | B2: Abertura/Expansão
A3: 11374979
A4: 11997870
A5: 11930537
A6: 11899381
A7: 11899592
A8: 11889399
A9: 11842866
A10: 11843011
A11: 11684556
A12: 11685062
A13: 11698167
A14: 11698312
... A16: 11684264
A17: 11357814 | B17: Ações de marketing/vendas
A18: 11842580
A19: 11842668
A20: 11806208
A21: 11817123
A22: 11774094
A23: 11741460
A24: 11741181
A25: 11698497
A26: 11698513
A27: 11698524
A28: 11699034
A29: 11741070
A30: 10566142 | B30: Abertura/Expansão
A31: 10572176 | B31: Planejamento estratégico
A32: 10581011 | B32: Planejamento estratégico
A33: 10621157 | B33: Ações de marketing/vendas
A34: 10608029 | B34: Ações de marketing/vendas
A35: 10590212 | B35: Outro
A36: 10590859 | B36: Consultoria
A37: 11390110 | B37: Ações de marketing/vendas
A38: 11899460
A39: 11269120 | B39: Abertura/Expansão
A40: 11344672 | B40: Planejamento estratégico
A41: 11269632 | B41: Abertura/Expansão
...
